Workbook

Sheet Summary
A1: Smart Farm — DIY Bill of Materials
A2: 10-acre mixed farm, rural Karnataka — DIY electronics for the Smart Farm AI System blueprint
A4: Subsystem | B4: Total (Rs.) | C4: Phase
A5: A. Edge gateway & connectivity | B5: =BOM!F11 | C5: 1
A6: B. Solar power — control layer | B6: =BOM!F18 | C6: 1
A7: C. Irrigation control & water monitoring | B7: =BOM!F31 | C7: 1
A8: D. Soil monitoring — 6 zone nodes + 2 field stations | B8: =BOM!F42 | C8: 1–2
A9: E. Weather station | B9: =BOM!F53 | C9: 2
A10: F. Fertigation & venturi diffuser | B10: =BOM!F63 | C10: 2
A11: G. Livestock shed | B11: =BOM!F71 | C11: 2
A12: H. Cameras & security | B12: =BOM!F77 | C12: 1–2
A13: I. Pest & weed monitoring | B13: =BOM!F85 | C13: 2–3
A14: J. Wiring, protection & mounting | B14: =BOM!F93 | C14: all
A15: Subtotal — all subsystems | B15: =SUM(B5:B14)
A16: Contingency 10% (shipping, damage, retries) | B16: =B15*0.1
A17: GRAND TOTAL (DIY electronics) | B17: =B15+B16
A19: Basic tools (one-time, if not owned)
A20: Soldering iron + solder | B20: 800
A21: Crimping tool + lugs/ferrules | B21: 900
A22: Multimeter | B22: 700
A23: Wire stripper | B23: 300
A24: Cordless drill + bits | B24: 2500
A25: PTFE tape, spanners for plumbing | B25: 500
A26: Tools subtotal | B26: =SUM(B20:B25)
A28: HOW TO USE: edit blue cells (Qty / Unit price) on the BOM sheet — all totals recalculate.
A29: Prices are indicative Jul 2026 retail (robu.in, amazon.in, local electrical market), GST included; get quotes before ordering.
A30: Excluded and bought instead (see BOM sheet foot): cattle collars, drip system (PMKSY vendor), drone service, milk analyzer.
A31: Free software stack: ESPHome (nodes), Home Assistant + Node-RED (dashboard/logic), Frigate (cameras), all on the Pi.
A32: Compare: vendor-installed Phase 1+2 automation in the blueprint is ~Rs.9.6 lakh gross; this DIY electronics build covers the monitoring/control layer at a fraction, but with your labour and no AMC.

Sheet BOM
A1: Section | B1: Item | C1: Spec / example part | D1: Qty | E1: Unit (Rs.) | F1: Total (Rs.) | G1: Phase | H1: Notes
A2: A. Edge gateway & connectivity | B2: Raspberry Pi 4B 4GB | C2: Farm brain — Home Assistant + Node-RED + Frigate | D2: 1 | E2: 5500 | F2: =D2*E2 | G2: 1 | H2: Pi 5 4GB also fine (~Rs.6,500)
B3: microSD 64GB (high-endurance) | C3: SanDisk High Endurance class | D3: 1 | E3: 700 | F3: =D3*E3 | G3: 1 | H3: NVR/logging wears cheap cards out
B4: LoRa module SX1278 Ra-02 433 MHz | C4: Gateway radio | D4: 1 | E4: 350 | F4: =D4*E4 | G4: 1 | H4: Single-channel is enough for ~10 nodes
B5: ESP32 DevKit V1 | C5: LoRa-to-Pi serial bridge | D5: 1 | E5: 450 | F5: =D5*E5 | G5: 1
B6: 4G router, dual-SIM, ext. antenna port | C6: Tenda 4G03 Pro / TP-Link MR110 class | D6: 1 | E6: 6500 | F6: =D6*E6 | G6: 1 | H6: Jio + Airtel SIMs per blueprint
B7: Outdoor high-gain 4G antenna + SMA lead | C7: 10–12 dBi panel/yagi | D7: 1 | E7: 1200 | F7: =D7*E7 | G7: 1 | H7: Mount high at pump house
B8: SIM800L GSM module + antenna | C8: SMS fallback commands/alarms | D8: 1 | E8: 350 | F8: =D8*E8 | G8: 1 | H8: Own SIM, Rs.20/mo SMS pack
B9: DS3231 RTC module | C9: Keeps schedules through reboots | D9: 1 | E9: 150 | F9: =D9*E9 | G9: 1
B10: IP65 enclosure + DIN rail + glands | C10: 300x200 ABS, gateway box | D10: 1 | E10: 1200 | F10: =D10*E10 | G10: 1
B11: Subtotal — A. Edge gateway & connectivity | F11: =SUM(F2:F10)
A13: B. Solar power — control layer | B13: Solar panel 200 W 12 V | C13: Poly/mono, control system only | D13: 1 | E13: 6000 | F13: =D13*E13 | G13: 1 | H13: Pump stays on grid/diesel
B14: LiFePO4 battery 12.8 V 50 Ah | C14: 3+ days autonomy for controls | D14: 1 | E14: 11000 | F14: =D14*E14 | G14: 1 | H14: Lead-acid 100 Ah alt: Rs.9,500, 1/3 the life
B15: MPPT charge controller 20 A | C15: 12/24 V auto | D15: 1 | E15: 2500 | F15: =D15*E15 | G15: 1
B16: DC-DC buck 12->5 V 3 A | C16: Per node / Pi supply | D16: 4 | E16: 200 | F16: =D16*E16 | G16: 1
B17: Fuses, MC4 pairs, 6 mm2 solar cable set | D17: 1 | E17: 1500 | F17: =D17*E17 | G17: 1
B18: Subtotal — B. Solar power — control layer | F18: =SUM(F13:F17)
A20: C. Irrigation control & water monitoring | B20: Solenoid valve 1" 12 V DC, normally-closed | C20: Plastic body, drip-rated | D20: 6 | E20: 1400 | F20: =D20*E20 | G20: 1 | H20: One per zone; NC = fails shut
B21: Valve-controller node (ESP32 + 4-ch relay + box) | C21: Each drives 3 valves | D21: 2 | E21: 1600 | F21: =D21*E21 | G21: 1
B22: Flow meter YF-B10 1" brass, pulse | C22: Main line + fertigation line | D22: 2 | E22: 1000 | F22: =D22*E22 | G22: 1
B23: Pressure transducer 0–10 bar 1/4" | C23: Leak / burst / clog detection | D23: 2 | E23: 1400 | F23: =D23*E23 | G23: 1
B24: Borewell level sensor 0–50 m, 4–20 mA | C24: Submersible hydrostatic | D24: 1 | E24: 4500 | F24: =D24*E24 | G24: 1 | H24: Blueprint 4.1: watch falling yield
B25: 4–20 mA receiver board | C25: For borewell sensor | D25: 1 | E25: 400 | F25: =D25*E25 | G25: 1
B26: Ultrasonic level sensor JSN-SR04T | C26: Overhead tank % | D26: 1 | E26: 450 | F26: =D26*E26 | G26: 1 | H26: Waterproof probe
B27: Phase-failure relay | C27: Single-phasing protection | D27: 1 | E27: 1200 | F27: =D27*E27 | G27: 1 | H27: Pairs with existing starter
B28: PZEM-004T 100 A + CT | C28: Pump energy metering (kWh) | D28: 1 | E28: 900 | F28: =D28*E28 | G28: 1
B29: Pump-house node (ESP32 + SIM800 + box) | C29: GSM start/stop + dry-run logic | D29: 1 | E29: 1500 | F29: =D29*E29 | G29: 1 | H29: DIY 'Kisan Raja'
B30: 30 A relay/contactor driver module | C30: Drives pump contactor coil | D30: 1 | E30: 600 | F30: =D30*E30 | G30: 1
B31: Subtotal — C. Irrigation control & water monitoring | F31: =SUM(F20:F30)
A33: D. Soil monitoring — 6 zone nodes + 2 field stations | B33: Soil node kit (ESP32 + Ra-02 LoRa) | C33: One per zone | D33: 6 | E33: 750 | F33: =D33*E33 | G33: 1–2
B34: Capacitive soil moisture probe v2 | C34: 2 depths per zone; seal with epoxy | D34: 12 | E34: 120 | F34: =D34*E34 | G34: 1–2 | H34: Never use resistive probes — they corrode
B35: DS18B20 waterproof soil temperature | C35: One per zone | D35: 6 | E35: 150 | F35: =D35*E35 | G35: 1–2
B36: 2x 18650 + TP4056 + holder | C36: Per node battery pack | D36: 6 | E36: 350 | F36: =D36*E36 | G36: 1–2
B37: 6 V 2 W solar top-up panel | C37: Per node | D37: 6 | E37: 250 | F37: =D37*E37 | G37: 1–2
B38: IP65 node enclosure + mounting pole | D38: 6 | E38: 500 | F38: =D38*E38 | G38: 1–2
B39: pH kit: E-201 probe + driver board | C39: Field stations A & B | D39: 2 | E39: 1800 | F39: =D39*E39 | G39: 1–2 | H39: Recalibrate monthly (pH 4/7 buffers)
B40: Analog EC kit, K=1 probe | C40: Field stations A & B + dose feedback | D40: 2 | E40: 2000 | F40: =D40*E40 | G40: 1–2 | H40: DFRobot-class; generic TDS boards drift
B41: ADS1115 16-bit ADC | C41: Clean analog reads for pH/EC | D41: 2 | E41: 250 | F41: =D41*E41 | G41: 1–2
B42: Subtotal — D. Soil monitoring — 6 zone nodes + 2 field stations | F42: =SUM(F33:F41)
A44: E. Weather station | B44: Cup anemometer, pulse output | C44: Wind speed (spray windows) | D44: 1 | E44: 2500 | F44: =D44*E44 | G44: 2
...
